--- START: [2023-09-14 15:47:40]  ---
Traceback (most recent call last):
  File "pipeline.py", line 1, in <module>
    with open('push from google sheets to db.py', 'r') as file: exec(file.read())
  File "<string>", line 6, in <module>
  File "/code/code/library/.build/../../utils/google_sheet_utils.py", line 2, in <module>
    from google.auth.transport.requests import Request
ModuleNotFoundError: No module named 'google'
[main f773406] routine update
 2 files changed, 35 insertions(+)
 create mode 100644 .build/.log
 create mode 100755 .build/build
error: src refspec master does not match any
error: failed to push some refs to 'https://github.com/Polarization-Research-Lab/library.git'
--- FIN: [2023-09-14 15:47:40]  ---
============
--- START: [2023-09-14 15:52:13]  ---
Traceback (most recent call last):
  File "pipeline.py", line 1, in <module>
    with open('push from google sheets to db.py', 'r') as file: exec(file.read())
  File "<string>", line 6, in <module>
  File "/code/code/library/.build/../../utils/google_sheet_utils.py", line 2, in <module>
    from google.auth.transport.requests import Request
ModuleNotFoundError: No module named 'google'
--- START: [2023-09-14 15:52:47]  ---
Traceback (most recent call last):
  File "pipeline.py", line 1, in <module>
    with open('push from google sheets to db.py', 'r') as file: exec(file.read())
  File "<string>", line 6, in <module>
  File "/code/code/library/.build/../../utils/google_sheet_utils.py", line 2, in <module>
    from google.auth.transport.requests import Request
ModuleNotFoundError: No module named 'google'
--- START: [2023-09-14 15:54:23]  ---
[main 5ae4806] routine update
 5 files changed, 362 insertions(+), 1 deletion(-)
 create mode 100644 _posts/2014-09-09-26.md
 create mode 100644 _posts/2020-08-14-28.md
 create mode 100644 _posts/2022-06-01-27.md
To https://github.com/Polarization-Research-Lab/library.git
   26891b2..5ae4806  main -> main
--- FIN: [2023-09-14 15:54:27]  ---
============
--- START: [2023-09-15 00:00:02]  ---
Traceback (most recent call last):
  File "/code/code/.envs/py3/lib/python3.8/site-packages/urllib3/connection.py", line 174, in _new_conn
    conn = connection.create_connection(
  File "/code/code/.envs/py3/lib/python3.8/site-packages/urllib3/util/connection.py", line 72, in create_connection
    for res in socket.getaddrinfo(host, port, family, socket.SOCK_STREAM):
  File "/usr/lib/python3.8/socket.py", line 918, in getaddrinfo
    for res in _socket.getaddrinfo(host, port, family, type, proto, flags):
socket.gaierror: [Errno -3] Temporary failure in name resolution

During handling of the above exception, another exception occurred:

Traceback (most recent call last):
  File "/code/code/.envs/py3/lib/python3.8/site-packages/urllib3/connectionpool.py", line 714, in urlopen
    httplib_response = self._make_request(
  File "/code/code/.envs/py3/lib/python3.8/site-packages/urllib3/connectionpool.py", line 403, in _make_request
    self._validate_conn(conn)
  File "/code/code/.envs/py3/lib/python3.8/site-packages/urllib3/connectionpool.py", line 1053, in _validate_conn
    conn.connect()
  File "/code/code/.envs/py3/lib/python3.8/site-packages/urllib3/connection.py", line 363, in connect
    self.sock = conn = self._new_conn()
  File "/code/code/.envs/py3/lib/python3.8/site-packages/urllib3/connection.py", line 186, in _new_conn
    raise NewConnectionError(
urllib3.exceptions.NewConnectionError: <urllib3.connection.HTTPSConnection object at 0x7f6b39b0d610>: Failed to establish a new connection: [Errno -3] Temporary failure in name resolution

During handling of the above exception, another exception occurred:

Traceback (most recent call last):
  File "/code/code/.envs/py3/lib/python3.8/site-packages/requests/adapters.py", line 486, in send
    resp = conn.urlopen(
  File "/code/code/.envs/py3/lib/python3.8/site-packages/urllib3/connectionpool.py", line 798, in urlopen
    retries = retries.increment(
  File "/code/code/.envs/py3/lib/python3.8/site-packages/urllib3/util/retry.py", line 592, in increment
    raise MaxRetryError(_pool, url, error or ResponseError(cause))
urllib3.exceptions.MaxRetryError: HTTPSConnectionPool(host='oauth2.googleapis.com', port=443): Max retries exceeded with url: /token (Caused by NewConnectionError('<urllib3.connection.HTTPSConnection object at 0x7f6b39b0d610>: Failed to establish a new connection: [Errno -3] Temporary failure in name resolution'))

During handling of the above exception, another exception occurred:

Traceback (most recent call last):
  File "/code/code/.envs/py3/lib/python3.8/site-packages/google/auth/transport/requests.py", line 186, in __call__
    response = self.session.request(
  File "/code/code/.envs/py3/lib/python3.8/site-packages/requests/sessions.py", line 589, in request
    resp = self.send(prep, **send_kwargs)
  File "/code/code/.envs/py3/lib/python3.8/site-packages/requests/sessions.py", line 703, in send
    r = adapter.send(request, **kwargs)
  File "/code/code/.envs/py3/lib/python3.8/site-packages/requests/adapters.py", line 519, in send
    raise ConnectionError(e, request=request)
requests.exceptions.ConnectionError: HTTPSConnectionPool(host='oauth2.googleapis.com', port=443): Max retries exceeded with url: /token (Caused by NewConnectionError('<urllib3.connection.HTTPSConnection object at 0x7f6b39b0d610>: Failed to establish a new connection: [Errno -3] Temporary failure in name resolution'))

The above exception was the direct cause of the following exception:

Traceback (most recent call last):
  File "pipeline.py", line 1, in <module>
    with open('push from google sheets to db.py', 'r') as file: exec(file.read())
  File "<string>", line 13, in <module>
  File "/code/code/library/.build/../../utils/google_sheet_utils.py", line 17, in pull
    creds.refresh(Request())
  File "/code/code/.envs/py3/lib/python3.8/site-packages/google/oauth2/credentials.py", line 344, in refresh
    ) = reauth.refresh_grant(
  File "/code/code/.envs/py3/lib/python3.8/site-packages/google/oauth2/reauth.py", line 332, in refresh_grant
    response_status_ok, response_data, retryable_error = _client._token_endpoint_request_no_throw(
  File "/code/code/.envs/py3/lib/python3.8/site-packages/google/oauth2/_client.py", line 215, in _token_endpoint_request_no_throw
    request_succeeded, response_data, retryable_error = _perform_request()
  File "/code/code/.envs/py3/lib/python3.8/site-packages/google/oauth2/_client.py", line 191, in _perform_request
    response = request(
  File "/code/code/.envs/py3/lib/python3.8/site-packages/google/auth/transport/requests.py", line 192, in __call__
    raise new_exc from caught_exc
google.auth.exceptions.TransportError: HTTPSConnectionPool(host='oauth2.googleapis.com', port=443): Max retries exceeded with url: /token (Caused by NewConnectionError('<urllib3.connection.HTTPSConnection object at 0x7f6b39b0d610>: Failed to establish a new connection: [Errno -3] Temporary failure in name resolution'))
--- START: [2023-09-16 00:00:01]  ---
[main 9082767] routine update
 1 file changed, 78 insertions(+)
fatal: could not read Username for 'https://github.com': No such device or address
--- START: [2023-09-17 00:00:01]  ---
[main 5a93010] routine update
 1 file changed, 4 insertions(+)
fatal: could not read Username for 'https://github.com': No such device or address
--- START: [2023-09-18 00:00:01]  ---
[main 254842f] routine update
 1 file changed, 4 insertions(+)
fatal: could not read Username for 'https://github.com': No such device or address
--- START: [2023-09-19 00:00:01]  ---
[main c730b6e] routine update
 1 file changed, 1 insertion(+)
To https://github.com/Polarization-Research-Lab/library.git
   7998c35..c730b6e  main -> main
--- FIN: [2023-09-19 00:00:05]  ---
============
--- START: [2023-09-21 12:30:42]  ---
[main 77aa1e5] routine update
 9 files changed, 391 insertions(+), 10 deletions(-)
 create mode 100644 _posts/2017-10-20-31.md
 create mode 100644 _posts/2019-01-01-30.md
 create mode 100644 _posts/2021-07-01-29.md
 create mode 100644 assets/img/Armaly-Enders-2021_Holliday.png
fatal: could not read Username for 'https://github.com': No such device or address
--- START: [2023-09-21 13:42:41]  ---
Traceback (most recent call last):
  File "pipeline.py", line 1, in <module>
    with open('push from google sheets to db.py', 'r') as file: exec(file.read())
  File "<string>", line 35, in <module>
  File "/prl/code/.envs/py3/lib/python3.8/site-packages/sqlalchemy/orm/session.py", line 2262, in execute
    return self._execute_internal(
  File "/prl/code/.envs/py3/lib/python3.8/site-packages/sqlalchemy/orm/session.py", line 2153, in _execute_internal
    result = conn.execute(
  File "/prl/code/.envs/py3/lib/python3.8/site-packages/sqlalchemy/engine/base.py", line 1412, in execute
    return meth(
  File "/prl/code/.envs/py3/lib/python3.8/site-packages/sqlalchemy/sql/elements.py", line 515, in _execute_on_connection
    return connection._execute_clauseelement(
  File "/prl/code/.envs/py3/lib/python3.8/site-packages/sqlalchemy/engine/base.py", line 1627, in _execute_clauseelement
    compiled_sql, extracted_params, cache_hit = elem._compile_w_cache(
  File "/prl/code/.envs/py3/lib/python3.8/site-packages/sqlalchemy/sql/elements.py", line 703, in _compile_w_cache
    compiled_sql = self._compiler(
  File "/prl/code/.envs/py3/lib/python3.8/site-packages/sqlalchemy/sql/elements.py", line 315, in _compiler
    return dialect.statement_compiler(dialect, self, **kw)
  File "/prl/code/.envs/py3/lib/python3.8/site-packages/sqlalchemy/sql/compiler.py", line 1426, in __init__
    Compiled.__init__(self, dialect, statement, **kwargs)
  File "/prl/code/.envs/py3/lib/python3.8/site-packages/sqlalchemy/sql/compiler.py", line 867, in __init__
    self.string = self.process(self.statement, **compile_kwargs)
  File "/prl/code/.envs/py3/lib/python3.8/site-packages/sqlalchemy/sql/compiler.py", line 912, in process
    return obj._compiler_dispatch(self, **kwargs)
  File "/prl/code/.envs/py3/lib/python3.8/site-packages/sqlalchemy/sql/visitors.py", line 143, in _compiler_dispatch
    return meth(self, **kw)  # type: ignore  # noqa: E501
  File "/prl/code/.envs/py3/lib/python3.8/site-packages/sqlalchemy/sql/compiler.py", line 6047, in visit_update
    crud_params_struct = crud._get_crud_params(
  File "/prl/code/.envs/py3/lib/python3.8/site-packages/sqlalchemy/sql/crud.py", line 335, in _get_crud_params
    raise exc.CompileError(
sqlalchemy.exc.CompileError: Unconsumed column names: Full citation (APA style), Date published , Bibtex entry , Your name , Article title , Article authors (in order) 
